Workbook

Sheet Bill of Materials
A1: IoT Smart Home Controller - Bill of Materials
A2: ENGI30000 Capstone Project | Sheridan College | December 2025
A4: Item # | B4: Category | C4: Component | D4: Description | E4: Qty | F4: Unit Price (CAD) | G4: Extended Price | H4: Supplier | I4: Part Number/Notes
A5: MICROCONTROLLER & DEVELOPMENT
A6: 1 | B6: MCU | C6: ESP32-WROOM-32 DevKit | D6: Dual-core 240MHz, WiFi/BT, 4MB Flash | E6: 1 | F6: 12.99 | G6: =E6*F6 -> 12.99 | H6: Amazon/AliExpress | I6: ESP32-DevKitC-32
A7: 2 | B7: MCU | C7: USB Cable (Micro-B) | D7: Data + Power cable for ESP32 | E7: 1 | F7: 3.99 | G7: =E7*F7 -> 3.99 | H7: Amazon | I7: Generic
A8: SENSORS
A9: 3 | B9: Sensor | C9: DHT22 (AM2302) | D9: Digital Temp/Humidity, ±0.5°C, ±2-5%RH | E9: 1 | F9: 8.99 | G9: =E9*F9 -> 8.99 | H9: Amazon/AliExpress | I9: AM2302
A10: 4 | B10: Sensor | C10: 10kΩ Resistor | D10: Pull-up resistor for DHT22 data line | E10: 2 | F10: 0.1 | G10: =E10*F10 -> 0.2 | H10: DigiKey/Mouser | I10: 1/4W 5%
A11: RELAY & SWITCHING
A12: 5 | B12: Relay | C12: 4-Channel Relay Module | D12: 5V relay, 10A @ 250VAC per channel | E12: 1 | F12: 7.99 | G12: =E12*F12 -> 7.99 | H12: Amazon/AliExpress | I12: HL-54S V1.0
A13: 6 | B13: Relay | C13: Screw Terminal Block | D13: 2-pin, 5.08mm pitch for relay wiring | E13: 8 | F13: 0.35 | G13: =E13*F13 -> 2.8 | H13: DigiKey/Mouser | I13: KF301-2P
A14: POWER SUPPLY
A15: 7 | B15: Power | C15: 5V 2A USB Adapter | D15: Power supply for ESP32 and relays | E15: 1 | F15: 8.99 | G15: =E15*F15 -> 8.99 | H15: Amazon | I15: UL Listed
A16: 8 | B16: Power | C16: 100µF Electrolytic Cap | D16: 16V, bulk filtering capacitor | E16: 2 | F16: 0.25 | G16: =E16*F16 -> 0.5 | H16: DigiKey/Mouser | I16: Aluminum electrolytic
A17: 9 | B17: Power | C17: 10µF Ceramic Cap | D17: 16V, high-freq noise filtering | E17: 3 | F17: 0.15 | G17: =E17*F17 -> 0.45 | H17: DigiKey/Mouser | I17: MLCC X7R
A18: 10 | B18: Power | C18: 0.1µF Ceramic Cap | D18: 16V, decoupling capacitor | E18: 4 | F18: 0.1 | G18: =E18*F18 -> 0.4 | H18: DigiKey/Mouser | I18: MLCC X7R
A19: LED INDICATORS
A20: 11 | B20: LED | C20: Red LED 3mm | D20: Error/fault indicator | E20: 2 | F20: 0.15 | G20: =E20*F20 -> 0.3 | H20: DigiKey/Mouser | I20: Diffused
A21: 12 | B21: LED | C21: Green LED 3mm | D21: Status/relay ON indicator | E21: 4 | F21: 0.15 | G21: =E21*F21 -> 0.6 | H21: DigiKey/Mouser | I21: Diffused
A22: 13 | B22: LED | C22: Blue LED 3mm | D22: WiFi/connection status | E22: 2 | F22: 0.2 | G22: =E22*F22 -> 0.4 | H22: DigiKey/Mouser | I22: Diffused
A23: 14 | B23: LED | C23: 330Ω Resistor | D23: Current limiting for LEDs (3.3V) | E23: 8 | F23: 0.05 | G23: =E23*F23 -> 0.4 | H23: DigiKey/Mouser | I23: 1/4W 5%
A24: PCB & CONNECTORS
A25: 15 | B25: PCB | C25: Custom PCB | D25: Multi-layer, fabricated from Eagle design | E25: 1 | F25: 15 | G25: =E25*F25 -> 15 | H25: JLCPCB/PCBWay | I25: IOT.fbrd
A26: 16 | B26: Connector | C26: Female Header 19-pin | D26: For ESP32 DevKit mounting (2 required) | E26: 2 | F26: 1.25 | G26: =E26*F26 -> 2.5 | H26: DigiKey/Mouser | I26: 2.54mm pitch
A27: 17 | B27: Connector | C27: Male Header Strip | D27: 40-pin breakaway for GPIO | E27: 1 | F27: 0.99 | G27: =E27*F27 -> 0.99 | H27: Amazon/AliExpress | I27: 2.54mm pitch
A28: 18 | B28: Connector | C28: 3-Pin Header | D28: For DHT22 sensor connection | E28: 1 | F28: 0.25 | G28: =E28*F28 -> 0.25 | H28: DigiKey/Mouser | I28: 2.54mm pitch
A29: 19 | B29: Connector | C29: JST-XH 4-Pin | D29: For relay module connection | E29: 1 | F29: 0.5 | G29: =E29*F29 -> 0.5 | H29: DigiKey/Mouser | I29: 2.5mm pitch
A30: ENCLOSURE & MISCELLANEOUS
A31: 20 | B31: Enclosure | C31: Project Box | D31: ABS plastic enclosure, 100x68x50mm | E31: 1 | F31: 5.99 | G31: =E31*F31 -> 5.99 | H31: Amazon | I31: IP65 Optional
A32: 21 | B32: Misc | C32: Standoff Kit | D32: M3 nylon standoffs for PCB mounting | E32: 1 | F32: 4.99 | G32: =E32*F32 -> 4.99 | H32: Amazon | I32: M3 Assorted
A33: 22 | B33: Misc | C33: Heat Shrink Tubing | D33: Assorted sizes for wire protection | E33: 1 | F33: 3.99 | G33: =E33*F33 -> 3.99 | H33: Amazon | I33: 2:1 ratio
A34: 23 | B34: Misc | C34: Hook-up Wire | D34: 22 AWG stranded, assorted colors | E34: 1 | F34: 6.99 | G34: =E34*F34 -> 6.99 | H34: Amazon | I34: 6 colors, 10m each
A35: 24 | B35: Misc | C35: Solder Wire | D35: 60/40 Rosin core, 0.8mm | E35: 1 | F35: 7.99 | G35: =E35*F35 -> 7.99 | H35: Amazon | I35: Lead-free optional
A37: SUBTOTAL (Components) | G37: =SUM(G6:G35) -> 98.19
A38: Estimated Shipping | G38: 10
A39: Estimated Tax (13% HST) | G39: =G37*0.13 -> 12.7647
A40: GRAND TOTAL | G40: =G37+G38+G39 -> 120.9547
A43: NOTES & ASSUMPTIONS
A44: 1. Prices are estimates based on typical online retailers (Amazon, AliExpress, DigiKey, Mouser) as of December 2025.
...

Sheet Summary
A1: BOM SUMMARY
A3: Category | B3: Item Count | C3: Cost (CAD)
A4: Microcontroller & Dev | B4: 2 | C4: ='Bill of Materials'!G6+'Bill of Materials'!G7 -> 16.98
A5: Sensors | B5: 2 | C5: ='Bill of Materials'!G9+'Bill of Materials'!G10 -> 9.19
A6: Relay & Switching | B6: 2 | C6: ='Bill of Materials'!G12+'Bill of Materials'!G13 -> 10.79
A7: Power Supply | B7: 4 | C7: ='Bill of Materials'!G15+'Bill of Materials'!G16+'Bill of Materials'!G17+'Bill of Materials'!G18 -> 10.34
A8: LED Indicators | B8: 4 | C8: ='Bill of Materials'!G20+'Bill of Materials'!G21+'Bill of Materials'!G22+'Bill of Materials'!G23 -> 1.7
A9: PCB & Connectors | B9: 5 | C9: ='Bill of Materials'!G25+'Bill of Materials'!G26+'Bill of Materials'!G27+'Bill of Materials'!G28+'Bill of Materials'!G29 -> 19.24
A10: Enclosure & Misc | B10: 5 | C10: ='Bill of Materials'!G31+'Bill of Materials'!G32+'Bill of Materials'!G33+'Bill of Materials'!G34+'Bill of Materials'!G35 -> 29.95
A11: TOTAL | B11: =SUM(B4:B10) -> 24 | C11: =SUM(C4:C10) -> 98.19
A14: Project: IoT Smart Home Controller
A15: Course: ENGI30000 Capstone
A16: Team: Aryan Prajapati, Manav Parikh, Dev Patel
A17: Date: December 2025
